Workbook

Sheet Leia-me
A1: Sprout — Modelo financeiro 2027–2031
A2: Gerado por docs/business-plan/modelo/build_model.py a partir de pressupostos.json · data de referência 13-10-2026 · euros correntes, sem IVA
A4: Resultados-chave (ligados à folha Cenários)
A5: Indicador | B5: Unidade | C5: Pessimista | D5: Base | E5: Otimista | F5: Recomendado
A6: EBITDA 2031 | B6: € | C6: =Cenários!G66 -> -931281.49 | D6: =Cenários!G67 -> -1219975.9 | E6: =Cenários!G68 -> -906159.63 | F6: =Cenários!G69 -> -529540.38
A7: Resultado líquido 2031 | B7: € | C7: =Cenários!G70 -> -953731.49 | D7: =Cenários!G71 -> -1261509.2 | E7: =Cenários!G72 -> -967992.97 | F7: =Cenários!G73 -> -569323.71
A8: GMV 2031 | B8: € | C8: =Cenários!G10 -> 2823480 | D8: =Cenários!G11 -> 11142350 | E8: =Cenários!G12 -> 17469500 | F8: =Cenários!G13 -> 22483000
A9: Cash flow acumulado para o acionista, 2027–2031 | B9: € | C9: =Cenários!G78 -> -4277080.6 | D9: =Cenários!G79 -> -5213753.7 | E9: =Cenários!G80 -> -4836437.5 | F9: =Cenários!G81 -> -3726708.2
A10: Necessidade de capital próprio (pico no horizonte) | B10: € | C10: =Cenários!C109 -> 4572080.6 | D10: =Cenários!D109 -> 5508753.7 | E10: =Cenários!E109 -> 5131437.5 | F10: =Cenários!F109 -> 4021708.2
A11: Break-even do EBITDA | B11: mês | C11: =Cenários!C113 -> não atinge até 2031 | D11: =Cenários!D113 -> não atinge até 2031 | E11: =Cenários!E113 -> não atinge até 2031 | F11: =Cenários!F113 -> não atinge até 2031
A12: 1.º ano com cash flow para o acionista ≥ 0 | B12: ano | C12: =Cenários!C115 -> não atinge até 2031 | D12: =Cenários!D115 -> não atinge até 2031 | E12: =Cenários!E115 -> não atinge até 2031 | F12: =Cenários!F115 -> não atinge até 2031
A13: Verificações do modelo (Cenários, secção 5) | C13: =Cenários!C150 -> OK
A16: Para que serve | B16: Testar, com números rastreáveis, se a tese do documento-fonte (marketplace B2B de azeite, água e café com desconto de 10–15%, captura de 80–90% da margem do embalador e investidores a 18 meses) fecha, e qual é o caminho para a viabilidade que a investigação aponta.
B17: Leitores: fundadores, Gonçalo Almeida (jurídico), Pedro Marques (operações, Lagar do Val) e investidores qualificados. Não é uma oferta de investimento.
A19: Resposta curta | B19: Os três cenários do documento-fonte, com as 53 correções verificadas e sem ajustes, não chegam ao break-even até 2031: a margem por kg não paga a estrutura.
B20: O cenário Recomendado (reestruturado) muda o produto, os canais e os custos como a investigação recomenda. O resultado está na tabela acima e na folha Cenários; não foi ajustado para dar break-even. A folha Sensibilidade mostra o caso com todas as alavancas no topo dos intervalos da investigação.
A22: Estrutura | B22: Pressupostos — todos os inputs, por cenário, com fonte; seletor do cenário ativo em C4.
B23: Unit economics — lotes-tipo de ponta a ponta (HoReCa 20 t, distribuidores 30 t, granel 100 t, água 20 paletes) nos quatro cenários; bolo de intermediação; teste da tese literal; risco de preço; piloto de 2027.
B24: Volumes, Receitas, Pessoal, Custos, DR, Cash flow, Capital & financiamento — o cenário ativo, ano a ano.
B25: Cenários — os quatro cenários lado a lado; o que tem de ser verdade; o que muda no Recomendado; verificações.
B26: Sensibilidade — desconto 10/12,5/15%, volumes ±30%, preço do AOVE −30% e topo dos intervalos (motor completo por caso), para o Base e o Recomendado; grelha captura × desconto da tese literal; perda no stock com choque de preço.
B27: Fontes — origem de cada pressuposto e registo de verificação. Motor — o cálculo em blocos fixos por cenário e caso (não editar).
A29: Como mudar de cenário | B29: Pressupostos!C4: escolher Pessimista, Base, Otimista ou Recomendado. Mudam as folhas de detalhe. Cenários, Unit economics e Sensibilidade mostram sempre cenários fixos.
B30: Para alterar um pressuposto: mudar a célula azul em Pressupostos (o livro recalcula). Para que a alteração passe aos PDF, mudar pressupostos.json e voltar a correr build_model.py, que regrava resultados.json.
A32: Código de cores | B32: Azul = input (editar só estas células). Preto = fórmula. Verde = ligação a outra folha. Amarelo = seletor de cenário.
A34: Convenções | B34: Preços das mercadorias constantes ao nível de out. 2026 (compra back-to-back, neutra ao nível de preço); salários +3%/ano; opex +2%/ano e 5% de contingência.
B35: Capital de giro = nível médio do ano por prazos médios (stock, recebimento, pagamento ao produtor a 30 dias). Obrigações = % do capital de giro ÷ utilização; 0% em 2027 (CSC art. 348.º/2 [L]).
B36: EBITDA inclui o cupão das obrigações como custo direto do lote (a SPV financia stock lote a lote), como no 01 e em calculo_referencia.py; a DR mostra também o EBITDA sem cupão.
B37: IRC com taxa PME, derramas municipal e estadual e reporte de prejuízos a 65% [L]. Imposto pago no próprio ano (simplificação).
B38: Break-even em mês = cruzamento do EBITDA mensal com zero, interpolando linearmente entre os pontos médios dos anos (estimativa).
A40: Avisos | B40: Itens [L] (CSC, RGICSF, PRIIPs, IRC, TSU, retenções) estão por confirmar pelo advogado e pelo contabilista certificado: o acesso a fontes primárias (DRE, EUR-Lex, Portal das Finanças) estava bloqueado na verificação.
B41: Itens NV (referência HoReCa, preço de saída do embalador, comissões, custos de custódia e 3PL) são hipóteses a medir no piloto, não promessas comerciais.
B42: Não existem futuros de azeite (MFAO extinto). Deter stock 18 meses sem cobertura arrisca perdas de 50–70% do lote (carry 19,8% + VaR95 37–57% − margem).

Sheet Pressupostos
A1: Pressupostos
A2: Todos os inputs do modelo (azul). Valores lidos de docs/business-plan/modelo/pressupostos.json em 13-10-2026. Etiquetas: [F] facto com fonte; [L] referência legal a confirmar; [E] estimativa; [I] inferência; NV não verificado.
A4: Cenário ativo (escolher na lista) | C4: Base | D4: índice | E4: =MATCH($C$4,$C$8:$F$8,0) -> 2
A5: Muda as folhas Volumes, Receitas, Pessoal, Custos, DR, Cash flow e Capital & financiamento. Cenários, Unit economics e Sensibilidade mostram cenários fixos (folha Motor).
A7: A. Pressupostos escalares por cenário
A8: Parâmetro | B8: Unidade | C8: Pessimista | D8: Base | E8: Otimista | F8: Recomendado | G8: Ativo | H8: Fonte / racional
A9: Azeite: preço do granel e prémios de origem
A10: Índice do granel AOVE (média 2 semanas SIMA + Poolred) | B10: €/kg | C10: 3.5 | D10: 3.5 | E10: 3.5 | F10: 3.5 | G10: =CHOOSE($E$4,C10,D10,E10,F10) -> 3.5 | H10: [F] SIMA 3,40–3,80 e Poolred 3,34 (out. 2026); 3,50 arredondado para cima; constante (compra back-to-back). 00 §1.2
A11: Prémio de origem pago ao lagar — HoReCa/gourmet | B11: €/kg | C11: 0.15 | D11: 0.1 | E11: 0.05 | F11: 0.15 | G11: =CHOOSE($E$4,C11,D11,E11,F11) -> 0.1 | H11: [E] lote individualizado com ficha analítica; Recomendado 0,15 (DOP/monovarietal, o prémio mais alto do conjunto verificado)
A12: Prémio de origem pago ao lagar — distribuidores/exportação | B12: €/kg | C12: 0.15 | D12: 0.1 | E12: 0.05 | F12: 0.1 | G12: =CHOOSE($E$4,C12,D12,E12,F12) -> 0.1 | H12: [E] igual ao HoReCa nos cenários do documento-fonte (calculo_referencia.py usa um só prémio)
A13: Prémio de origem pago ao lagar — granel certificado | B13: €/kg | C13: 0 | D13: 0 | E13: 0 | F13: 0 | G13: =CHOOSE($E$4,C13,D13,E13,F13) -> 0 | H13: [E] granel comprado ao índice: o lagar ganha prazo (≤ 30 dias por SCT Inst), não preço
A14: Azeite: canal HoReCa/gourmet
A15: Referência do comprador (cotação documentada do equivalente, s/ IVA) | B15: €/kg | C15: 5.4 | D15: 5.65 | E15: 6 | F15: 6 | G15: =CHOOSE($E$4,C15,D15,E15,F15) -> 5.65 | H15: [E, NV] equivalente de retalho standard 5,3–6,0; 6,00 só com origem identificada documentada (gate: ≥ 20 cotações). 00 §1.4; 01 §2.1
A16: Desconto ao comprador sobre a referência | B16: % | C16: 0.1 | D16: 0.1 | E16: 0.1 | F16: 0.1 | G16: =CHOOSE($E$4,C16,D16,E16,F16) -> 0.1 | H16: Documento-fonte 10–15%; 10% porque 15% leva a margem para ~1,4%. 01 §2.5
A17: Prazo médio de recebimento | B17: dias | C17: 45 | D17: 35 | E17: 30 | F17: 35 | G17: =CHOOSE($E$4,C17,D17,E17,F17) -> 35 | H17: [F] restauração: 30 dias de atraso médio, 11% paga a horas (Informa D&B mai. 2026); 35 dias com SDD B2B
A18: Provisão de crédito | B18: % vendas | C18: 0.008 | D18: 0.006 | E18: 0.005 | F18: 0.006 | G18: =CHOOSE($E$4,C18,D18,E18,F18) -> 0.006 | H18: [E] SDD B2B sem direito a reembolso + limites por cliente
A19: Azeite: canal distribuidores/exportação
A20: Referência = preço de saída do embalador | B20: €/kg | C20: 4.2 | D20: 4.35 | E20: 4.5 | F20: 4.35 | G20: =CHOOSE($E$4,C20,D20,E20,F20) -> 4.35 | H20: [E, NV] granel 3,50 + embalamento 0,47–0,51 + margem do embalador 0,19–0,50 = 4,16–4,51. 00 §1.4
A21: Prémio de origem verificada pago pelo comprador | B21: €/kg | C21: 0 | D21: 0 | E21: 0 | F21: 0.1 | G21: =CHOOSE($E$4,C21,D21,E21,F21) -> 0 | H21: [E] 0 no documento-fonte; Recomendado 0,10 = limite inferior da condição para a seed (0,10–0,20). 01 §5.4
A22: Desconto ao comprador | B22: % | C22: 0 | D22: 0 | E22: 0 | F22: 0 | G22: =CHOOSE($E$4,C22,D22,E22,F22) -> 0 | H22: 0%: qualquer desconto põe o canal abaixo do break-even (4,29 €/kg). 01 §2.5
A23: Stock médio | B23: dias | C23: 35 | D23: 30 | E23: 25 | F23: 30 | G23: =CHOOSE($E$4,C23,D23,E23,F23) -> 30 | H23: [E] paletes levantadas em ~60 dias
A24: Prazo médio de recebimento | B24: dias | C24: 55 | D24: 45 | E24: 40 | F24: 55 | G24: =CHOOSE($E$4,C24,D24,E24,F24) -> 45 | H24: [E] Recomendado 55 dias (mais exportação embalada; valor do pessimista)
A25: Provisão de crédito | B25: % vendas | C25: 0.005 | D25: 0.003 | E25: 0.003 | F25: 0.003 | G25: =CHOOSE($E$4,C25,D25,E25,F25) -> 0.003 | H25: [E]
A26: Outros pressupostos por cenário
A27: Água: comissão de agente sobre o GMV | B27: % | C27: 0.01 | D27: 0.02 | E27: 0.03 | F27: 0.02 | G27: =CHOOSE($E$4,C27,D27,E27,F27) -> 0.02 | H27: [E, NV] banda 0,5–3%; 4–5% só com cotação real de um engarrafador. 01 §6.1
A28: Café: ano de início | B28: ano | C28: 2029 | D28: 2029 | E28: 2028 | F28: 2030 | G28: =CHOOSE($E$4,C28,D28,E28,F28) -> 2029 | H28: [F] EUDR aplicável a 30-12-2026 (grandes/médios) e 30-06-2027 (micro/pequenos); Recomendado adia para 2030
A29: Café: custo de cobertura (forward EUR/USD; ICE > 50–100 t/ano) | B29: % compras | C29: 0 | D29: 0 | E29: 0 | F29: 0.003 | G29: =CHOOSE($E$4,C29,D29,E29,F29) -> 0 | H29: [E/NV] forward 0,1–0,5%; ICE < 0,5% do nocional por semestre. 40 §2.3–2.4
A30: Verificação para terceiros: parte dos custos suportada pela Sprout | B30: % | C30: 1 | D30: 1 | E30: 1 | F30: 0 | G30: =CHOOSE($E$4,C30,D30,E30,F30) -> 1 | H30: 1 = Sprout paga collateral manager e análises; 0 = banco/mutuário paga (alternativa da nota de custos)
A31: Utilização média do capital levantado nas séries | B31: % | C31: 0.7 | D31: 0.8 | E31: 0.85 | F31: 0.8 | G31: =CHOOSE($E$4,C31,D31,E31,F31) -> 0.8 | H31: [E] capital levantado a 12–18 meses vs. rotação do stock de 2–4 meses. 40 §5.1
A32: Ronda pré-seed (recebida até 31-01-2027) | B32: € | C32: 1100000 | D32: 1100000 | E32: 1100000 | F32: 1100000 | G32: =CHOOSE($E$4,C32,D32,E32,F32) -> 1100000 | H32: 01 §5.5 e §7.3: 1,1 M€ (ou 0,8 M€ + bridge firme de 0,3 M€)
A34: B. Constantes (iguais em todos os cenários)
A35: Parâmetro | B35: Unidade | C35: Valor | G35: Ativo | H35: Fonte / racional
A36: Azeite: canal HoReCa/gourmet (constantes)
A37: Embalamento no lagar (5 L PET/BIB e vidro) | B37: €/kg | C37: 0.55 | G37: =C37 -> 0.55 | H37: [F] Observatorio 0,47–0,51 €/kg + 0,05 pelo mix com vidro. 00 §1.4
A38: Armazém logístico (3PL) e picking | B38: €/kg | C38: 0.06 | G38: =C38 -> 0.06 | H38: [E, NV] encomendas de 20–50 kg a ~2–4 € cada
A39: Dimensão do lote-tipo | B39: t | C39: 20 | G39: =C39 -> 20 | H39: 01 §2.2
A40: Análises por lote (entrada + intermédia) | B40: n.º | C40: 2 | G40: =C40 -> 2 | H40: 40 §5.2
A41: Custódia (collateral manager) por lote | B41: €/lote | C41: 2000 | G41: =C41 -> 2000 | H41: [E, NV] 300–500 € por visita: entrada + ~3 tranches + fecho
A42: Pagamentos bancários (SEPA) | B42: €/kg | C42: 0.01 | G42: =C42 -> 0.01 | H42: [E] comissões por operação; KYC e faturação no custo fixo de tecnologia
A43: Azeite: canal distribuidores/exportação (constantes)
...

Sheet Unit economics
A1: Unit economics
A2: Lotes-tipo de ponta a ponta, por cenário (independente do seletor). Valores por kg lidos do Motor no ano de regime; lote = €/kg × dimensão do lote.
A3: Ano de regime dos lotes-tipo | C3: =Pressupostos!$C$187 -> 2029 | D3: =C3-2026 -> 3 | E3: ← índice do ano (1 = 2027); mude o ano em Pressupostos
A5: A. Lote de azeite HoReCa/gourmet (origem identificada; 5 L PET/BIB e vidro)
A6: Ponta a ponta no ano de regime (por lote e por kg)
A7: Rubrica | B7: Unidade | C7: Pessimista: € / lote | D7: Pessimista: €/kg | E7: Base: € / lote | F7: Base: €/kg | G7: Otimista: € / lote | H7: Otimista: €/kg | I7: Recomendado: € / lote | J7: Recomendado: €/kg | K7: Notas
A8: Dimensão do lote | B8: kg | C8: =Pressupostos!$C$39*1000 -> 20000 | E8: =Pressupostos!$C$39*1000 -> 20000 | G8: =Pressupostos!$C$39*1000 -> 20000 | I8: =Pressupostos!$C$39*1000 -> 20000
A9: Preço de referência do comprador (mercado) | B9: € | C9: =D9*$C$8 -> 108000 | D9: =INDEX(Motor!$C$28:$G$28,1,$D$3) -> 5.4 | E9: =F9*$E$8 -> 113000 | F9: =INDEX(Motor!$C$338:$G$338,1,$D$3) -> 5.65 | G9: =H9*$G$8 -> 120000 | H9: =INDEX(Motor!$C$648:$G$648,1,$D$3) -> 6 | I9: =J9*$I$8 -> 120000 | J9: =INDEX(Motor!$C$958:$G$958,1,$D$3) -> 6
A10: Desconto ao comprador | B10: € | C10: =D10*$C$8 -> -10800 | D10: =-(INDEX(Motor!$C$28:$G$28,1,$D$3)-INDEX(Motor!$C$29:$G$29,1,$D$3)) -> -0.54 | E10: =F10*$E$8 -> -11300 | F10: =-(INDEX(Motor!$C$338:$G$338,1,$D$3)-INDEX(Motor!$C$339:$G$339,1,$D$3)) -> -0.565 | G10: =H10*$G$8 -> -12000 | H10: =-(INDEX(Motor!$C$648:$G$648,1,$D$3)-INDEX(Motor!$C$649:$G$649,1,$D$3)) -> -0.6 | I10: =J10*$I$8 -> -12000 | J10: =-(INDEX(Motor!$C$958:$G$958,1,$D$3)-INDEX(Motor!$C$959:$G$959,1,$D$3)) -> -0.6
A11: Receita Sprout (preço de venda) | B11: € | C11: =D11*$C$8 -> 97200 | D11: =INDEX(Motor!$C$29:$G$29,1,$D$3) -> 4.86 | E11: =F11*$E$8 -> 101700 | F11: =INDEX(Motor!$C$339:$G$339,1,$D$3) -> 5.085 | G11: =H11*$G$8 -> 108000 | H11: =INDEX(Motor!$C$649:$G$649,1,$D$3) -> 5.4 | I11: =J11*$I$8 -> 108000 | J11: =INDEX(Motor!$C$959:$G$959,1,$D$3) -> 5.4
A12: Preço ao produtor (índice + prémio; pago ≤ 30 dias) | B12: € | C12: =D12*$C$8 -> -73000 | D12: =-INDEX(Motor!$C$27:$G$27,1,$D$3) -> -3.65 | E12: =F12*$E$8 -> -72000 | F12: =-INDEX(Motor!$C$337:$G$337,1,$D$3) -> -3.6 | G12: =H12*$G$8 -> -71000 | H12: =-INDEX(Motor!$C$647:$G$647,1,$D$3) -> -3.55 | I12: =J12*$I$8 -> -73000 | J12: =-INDEX(Motor!$C$957:$G$957,1,$D$3) -> -3.65
A13: Embalamento no lagar | B13: € | C13: =D13*$C$8 -> -11000 | D13: =-INDEX(Motor!$C$30:$G$30,1,$D$3) -> -0.55 | E13: =F13*$E$8 -> -11000 | F13: =-INDEX(Motor!$C$340:$G$340,1,$D$3) -> -0.55 | G13: =H13*$G$8 -> -11000 | H13: =-INDEX(Motor!$C$650:$G$650,1,$D$3) -> -0.55 | I13: =J13*$I$8 -> -11000 | J13: =-INDEX(Motor!$C$960:$G$960,1,$D$3) -> -0.55
A14: Logística | B14: € | C14: =D14*$C$8 -> -6200 | D14: =-INDEX(Motor!$C$31:$G$31,1,$D$3) -> -0.31 | E14: =F14*$E$8 -> -5600 | F14: =-INDEX(Motor!$C$341:$G$341,1,$D$3) -> -0.28 | G14: =H14*$G$8 -> -5200 | H14: =-INDEX(Motor!$C$651:$G$651,1,$D$3) -> -0.26 | I14: =J14*$I$8 -> -5600 | J14: =-INDEX(Motor!$C$961:$G$961,1,$D$3) -> -0.28
A15: Armazém logístico (3PL) e picking | B15: € | C15: =D15*$C$8 -> -1200 | D15: =-INDEX(Motor!$C$32:$G$32,1,$D$3) -> -0.06 | E15: =F15*$E$8 -> -1200 | F15: =-INDEX(Motor!$C$342:$G$342,1,$D$3) -> -0.06 | G15: =H15*$G$8 -> -1200 | H15: =-INDEX(Motor!$C$652:$G$652,1,$D$3) -> -0.06 | I15: =J15*$I$8 -> -1200 | J15: =-INDEX(Motor!$C$962:$G$962,1,$D$3) -> -0.06
A16: Armazenagem | B16: € | C16: =D16*$C$8 -> -480 | D16: =-INDEX(Motor!$C$35:$G$35,1,$D$3) -> -0.024 | E16: =F16*$E$8 -> -120 | F16: =-INDEX(Motor!$C$345:$G$345,1,$D$3) -> -0.006 | G16: =H16*$G$8 -> -120 | H16: =-INDEX(Motor!$C$655:$G$655,1,$D$3) -> -0.006 | I16: =J16*$I$8 -> -120 | J16: =-INDEX(Motor!$C$965:$G$965,1,$D$3) -> -0.006
A17: Seguro do stock | B17: € | C17: =D17*$C$8 -> -72 | D17: =-INDEX(Motor!$C$36:$G$36,1,$D$3) -> -0.0036 | E17: =F17*$E$8 -> -17.753425 | F17: =-INDEX(Motor!$C$346:$G$346,1,$D$3) -> -0.00088767123 | G17: =H17*$G$8 -> -17.506849 | H17: =-INDEX(Motor!$C$656:$G$656,1,$D$3) -> -0.00087534247 | I17: =J17*$I$8 -> -18 | J17: =-INDEX(Motor!$C$966:$G$966,1,$D$3) -> -0.0009
A18: Análises físico-químicas e painel (testes de qualidade) | B18: € | C18: =D18*$C$8 -> -600 | D18: =-INDEX(Motor!$C$37:$G$37,1,$D$3) -> -0.03 | E18: =F18*$E$8 -> -600 | F18: =-INDEX(Motor!$C$347:$G$347,1,$D$3) -> -0.03 | G18: =H18*$G$8 -> -600 | H18: =-INDEX(Motor!$C$657:$G$657,1,$D$3) -> -0.03 | I18: =J18*$I$8 -> -600 | J18: =-INDEX(Motor!$C$967:$G$967,1,$D$3) -> -0.03
A19: Perdas físicas | B19: € | C19: =D19*$C$8 -> -365 | D19: =-INDEX(Motor!$C$38:$G$38,1,$D$3) -> -0.01825 | E19: =F19*$E$8 -> -360 | F19: =-INDEX(Motor!$C$348:$G$348,1,$D$3) -> -0.018 | G19: =H19*$G$8 -> -355 | H19: =-INDEX(Motor!$C$658:$G$658,1,$D$3) -> -0.01775 | I19: =J19*$I$8 -> -365 | J19: =-INDEX(Motor!$C$968:$G$968,1,$D$3) -> -0.01825
A20: Desclassificação esperada | B20: € | C20: =D20*$C$8 -> -360 | D20: =-INDEX(Motor!$C$39:$G$39,1,$D$3) -> -0.018 | E20: =F20*$E$8 -> -90 | F20: =-INDEX(Motor!$C$349:$G$349,1,$D$3) -> -0.0045 | G20: =H20*$G$8 -> -90 | H20: =-INDEX(Motor!$C$659:$G$659,1,$D$3) -> -0.0045 | I20: =J20*$I$8 -> -90 | J20: =-INDEX(Motor!$C$969:$G$969,1,$D$3) -> -0.0045
A21: Custódia independente (collateral manager) | B21: € | C21: =D21*$C$8 -> -2000 | D21: =-INDEX(Motor!$C$40:$G$40,1,$D$3) -> -0.1 | E21: =F21*$E$8 -> -2000 | F21: =-INDEX(Motor!$C$350:$G$350,1,$D$3) -> -0.1 | G21: =H21*$G$8 -> -2000 | H21: =-INDEX(Motor!$C$660:$G$660,1,$D$3) -> -0.1 | I21: =J21*$I$8 -> -2000 | J21: =-INDEX(Motor!$C$970:$G$970,1,$D$3) -> -0.1
A22: Pagamentos bancários (SEPA; KYC/KYB no custo fixo) | B22: € | C22: =D22*$C$8 -> -200 | D22: =-INDEX(Motor!$C$41:$G$41,1,$D$3) -> -0.01 | E22: =F22*$E$8 -> -200 | F22: =-INDEX(Motor!$C$351:$G$351,1,$D$3) -> -0.01 | G22: =H22*$G$8 -> -200 | H22: =-INDEX(Motor!$C$661:$G$661,1,$D$3) -> -0.01 | I22: =J22*$I$8 -> -200 | J22: =-INDEX(Motor!$C$971:$G$971,1,$D$3) -> -0.01
A23: Provisão de crédito | B23: € | C23: =D23*$C$8 -> -777.6 | D23: =-INDEX(Motor!$C$42:$G$42,1,$D$3) -> -0.03888 | E23: =F23*$E$8 -> -610.2 | F23: =-INDEX(Motor!$C$352:$G$352,1,$D$3) -> -0.03051 | G23: =H23*$G$8 -> -540 | H23: =-INDEX(Motor!$C$662:$G$662,1,$D$3) -> -0.027 | I23: =J23*$I$8 -> -648 | J23: =-INDEX(Motor!$C$972:$G$972,1,$D$3) -> -0.0324
A24: Cobertura de preço explícita (azeite: sem futuros) | B24: € | C24: =D24*$C$8 -> 0 | D24: =-INDEX(Motor!$C$43:$G$43,1,$D$3) -> 0 | E24: =F24*$E$8 -> 0 | F24: =-INDEX(Motor!$C$353:$G$353,1,$D$3) -> 0 | G24: =H24*$G$8 -> 0 | H24: =-INDEX(Motor!$C$663:$G$663,1,$D$3) -> 0 | I24: =J24*$I$8 -> 0 | J24: =-INDEX(Motor!$C$973:$G$973,1,$D$3) -> 0
A25: Cupão das obrigações (retorno do investidor no ciclo) | B25: € | C25: =D25*$C$8 -> -4904.3836 | D25: =-INDEX(Motor!$C$44:$G$44,1,$D$3) -> -0.24521918 | E25: =F25*$E$8 -> -959.33219 | F25: =-INDEX(Motor!$C$354:$G$354,1,$D$3) -> -0.04796661 | G25: =H25*$G$8 -> -749.29895 | H25: =-INDEX(Motor!$C$664:$G$664,1,$D$3) -> -0.037464948 | I25: =J25*$I$8 -> -970.89041 | J25: =-INDEX(Motor!$C$974:$G$974,1,$D$3) -> -0.048544521
A26: Margem de contribuição do Sprout (spread da plataforma) | B26: € | C26: =D26*$C$8 -> -3958.9836 | D26: =INDEX(Motor!$C$46:$G$46,1,$D$3) -> -0.19794918 | E26: =F26*$E$8 -> 6942.7144 | F26: =INDEX(Motor!$C$356:$G$356,1,$D$3) -> 0.34713572 | G26: =H26*$G$8 -> 14928.194 | H26: =INDEX(Motor!$C$666:$G$666,1,$D$3) -> 0.74640971 | I26: =J26*$I$8 -> 12188.11 | J26: =INDEX(Motor!$C$976:$G$976,1,$D$3) -> 0.60940548
A27: Margem em % da receita | B27: % | D27: =IF(D11>0,D26/D11,0) -> -0.040730284 | F27: =IF(F11>0,F26/F11,0) -> 0.068266611 | H27: =IF(H11>0,H26/H11,0) -> 0.13822402 | J27: =IF(J11>0,J26/J11,0) -> 0.11285287
A28: Lado do investidor e almofada
A29: Capital imobilizado no lote (granel + embalamento) | B29: € | C29: =(INDEX(Motor!$C$27:$G$27,1,$D$3)+INDEX(Motor!$C$30:$G$30,1,$D$3))*$C$8 -> 84000 | E29: =(INDEX(Motor!$C$337:$G$337,1,$D$3)+INDEX(Motor!$C$340:$G$340,1,$D$3))*$E$8 -> 83000 | G29: =(INDEX(Motor!$C$647:$G$647,1,$D$3)+INDEX(Motor!$C$650:$G$650,1,$D$3))*$G$8 -> 82000 | I29: =(INDEX(Motor!$C$957:$G$957,1,$D$3)+INDEX(Motor!$C$960:$G$960,1,$D$3))*$I$8 -> 84000
A30: Ciclo líquido do capital (stock + recebimento − pagamento) | B30: dias | C30: =INDEX(Motor!$C$33:$G$33,1,$D$3)+INDEX(Motor!$C$34:$G$34,1,$D$3)-Pressupostos!$C$70 -> 195 | E30: =INDEX(Motor!$C$343:$G$343,1,$D$3)+INDEX(Motor!$C$344:$G$344,1,$D$3)-Pressupostos!$C$70 -> 50 | G30: =INDEX(Motor!$C$653:$G$653,1,$D$3)+INDEX(Motor!$C$654:$G$654,1,$D$3)-Pressupostos!$C$70 -> 45 | I30: =INDEX(Motor!$C$963:$G$963,1,$D$3)+INDEX(Motor!$C$964:$G$964,1,$D$3)-Pressupostos!$C$70 -> 50
A31: Parte do capital de giro financiada por obrigações | B31: % | C31: =INDEX(Pressupostos!$C$276:$G$276,1,$D$3) -> 0.85 | E31: =INDEX(Pressupostos!$C$277:$G$277,1,$D$3) -> 0.9 | G31: =INDEX(Pressupostos!$C$278:$G$278,1,$D$3) -> 0.9 | I31: =INDEX(Pressupostos!$C$279:$G$279,1,$D$3) -> 0.9
A32: Obrigações afetas ao lote (capital levantado = financiado ÷ utilização) | B32: € | C32: =INDEX(Pressupostos!$C$276:$G$276,1,$D$3)*(INDEX(Motor!$C$27:$G$27,1,$D$3)+INDEX(Motor!$C$30:$G$30,1,$D$3))*$C$8/Pressupostos!$C$31 -> 102000 | E32: =INDEX(Pressupostos!$C$277:$G$277,1,$D$3)*(INDEX(Motor!$C$337:$G$337,1,$D$3)+INDEX(Motor!$C$340:$G$340,1,$D$3))*$E$8/Pressupostos!$D$31 -> 93375 | G32: =INDEX(Pressupostos!$C$278:$G$278,1,$D$3)*(INDEX(Motor!$C$647:$G$647,1,$D$3)+INDEX(Motor!$C$650:$G$650,1,$D$3))*$G$8/Pressupostos!$E$31 -> 86823.529 | I32: =INDEX(Pressupostos!$C$279:$G$279,1,$D$3)*(INDEX(Motor!$C$957:$G$957,1,$D$3)+INDEX(Motor!$C$960:$G$960,1,$D$3))*$I$8/Pressupostos!$F$31 -> 94500
A33: Capital próprio do patrocinador no lote (subordinado) | B33: € | C33: =(1-INDEX(Pressupostos!$C$276:$G$276,1,$D$3))*(INDEX(Motor!$C$27:$G$27,1,$D$3)+INDEX(Motor!$C$30:$G$30,1,$D$3))*$C$8 -> 12600 | E33: =(1-INDEX(Pressupostos!$C$277:$G$277,1,$D$3))*(INDEX(Motor!$C$337:$G$337,1,$D$3)+INDEX(Motor!$C$340:$G$340,1,$D$3))*$E$8 -> 8300 | G33: =(1-INDEX(Pressupostos!$C$278:$G$278,1,$D$3))*(INDEX(Motor!$C$647:$G$647,1,$D$3)+INDEX(Motor!$C$650:$G$650,1,$D$3))*$G$8 -> 8200 | I33: =(1-INDEX(Pressupostos!$C$279:$G$279,1,$D$3))*(INDEX(Motor!$C$957:$G$957,1,$D$3)+INDEX(Motor!$C$960:$G$960,1,$D$3))*$I$8 -> 8400
A34: Cupão bruto anual | B34: % | C34: =INDEX(Pressupostos!$C$282:$G$282,1,$D$3) -> 0.09 | E34: =INDEX(Pressupostos!$C$283:$G$283,1,$D$3) -> 0.075 | G34: =INDEX(Pressupostos!$C$284:$G$284,1,$D$3) -> 0.07 | I34: =INDEX(Pressupostos!$C$285:$G$285,1,$D$3) -> 0.075
A35: Retorno líquido anual de um particular residente (retenção de 28%) | B35: % | C35: =INDEX(Pressupostos!$C$282:$G$282,1,$D$3)*(1-Pressupostos!$C$109) -> 0.0648 | E35: =INDEX(Pressupostos!$C$283:$G$283,1,$D$3)*(1-Pressupostos!$C$109) -> 0.054 | G35: =INDEX(Pressupostos!$C$284:$G$284,1,$D$3)*(1-Pressupostos!$C$109) -> 0.0504 | I35: =INDEX(Pressupostos!$C$285:$G$285,1,$D$3)*(1-Pressupostos!$C$109) -> 0.054
A36: Cupão pago no ciclo do lote | B36: € | C36: =INDEX(Motor!$C$44:$G$44,1,$D$3)*$C$8 -> 4904.3836 | E36: =INDEX(Motor!$C$354:$G$354,1,$D$3)*$E$8 -> 959.33219 | G36: =INDEX(Motor!$C$664:$G$664,1,$D$3)*$G$8 -> 749.29895 | I36: =INDEX(Motor!$C$974:$G$974,1,$D$3)*$I$8 -> 970.89041
A37: Retorno bruto do investidor no ciclo (% das obrigações afetas ao lote) | B37: % | C37: =IF(INDEX(Pressupostos!$C$276:$G$276,1,$D$3)>0,INDEX(Motor!$C$44:$G$44,1,$D$3)*$C$8/(INDEX(Pressupostos!$C$276:$G$276,1,$D$3)*(INDEX(Motor!$C$27:$G$27,1,$D$3)+INDEX(Motor!$C$30:$G$30,1,$D$3))*$C$8/Pressupostos!$C$31),0) -> 0.048082192 | E37: =IF(INDEX(Pressupostos!$C$277:$G$277,1,$D$3)>0,INDEX(Motor!$C$354:$G$354,1,$D$3)*$E$8/(INDEX(Pressupostos!$C$277:$G$277,1,$D$3)*(INDEX(Motor!$C$337:$G$337,1,$D$3)+INDEX(Motor!$C$340:$G$340,1,$D$3))*$E$8/Pressupostos!$D$31),0) -> 0.010273973 | G37: =IF(INDEX(Pressupostos!$C$278:$G$278,1,$D$3)>0,INDEX(Motor!$C$664:$G$664,1,$D$3)*$G$8/(INDEX(Pressupostos!$C$278:$G$278,1,$D$3)*(INDEX(Motor!$C$647:$G$647,1,$D$3)+INDEX(Motor!$C$650:$G$650,1,$D$3))*$G$8/Pressupostos!$E$31),0) -> 0.008630137 | I37: =IF(INDEX(Pressupostos!$C$279:$G$279,1,$D$3)>0,INDEX(Motor!$C$974:$G$974,1,$D$3)*$I$8/(INDEX(Pressupostos!$C$279:$G$279,1,$D$3)*(INDEX(Motor!$C$957:$G$957,1,$D$3)+INDEX(Motor!$C$960:$G$960,1,$D$3))*$I$8/Pressupostos!$F$31),0) -> 0.010273973
A38: Retida na reserva de primeira perda (30% da margem; teto 5% das obrigações do lote) | B38: € | C38: =MAX(0,MIN(Pressupostos!$C$108*INDEX(Motor!$C$46:$G$46,1,$D$3)*$C$8,Pressupostos!$C$107*INDEX(Pressupostos!$C$276:$G$276,1,$D$3)*(INDEX(Motor!$C$27:$G$27,1,$D$3)+INDEX(Motor!$C$30:$G$30,1,$D$3))*$C$8/Pressupostos!$C$31)) -> 0 | E38: =MAX(0,MIN(Pressupostos!$C$108*INDEX(Motor!$C$356:$G$356,1,$D$3)*$E$8,Pressupostos!$C$107*INDEX(Pressupostos!$C$277:$G$277,1,$D$3)*(INDEX(Motor!$C$337:$G$337,1,$D$3)+INDEX(Motor!$C$340:$G$340,1,$D$3))*$E$8/Pressupostos!$D$31)) -> 2082.8143 | G38: =MAX(0,MIN(Pressupostos!$C$108*INDEX(Motor!$C$666:$G$666,1,$D$3)*$G$8,Pressupostos!$C$107*INDEX(Pressupostos!$C$278:$G$278,1,$D$3)*(INDEX(Motor!$C$647:$G$647,1,$D$3)+INDEX(Motor!$C$650:$G$650,1,$D$3))*$G$8/Pressupostos!$E$31)) -> 4341.1765 | I38: =MAX(0,MIN(Pressupostos!$C$108*INDEX(Motor!$C$976:$G$976,1,$D$3)*$I$8,Pressupostos!$C$107*INDEX(Pressupostos!$C$279:$G$279,1,$D$3)*(INDEX(Motor!$C$957:$G$957,1,$D$3)+INDEX(Motor!$C$960:$G$960,1,$D$3))*$I$8/Pressupostos!$F$31)) -> 3656.4329
A39: Margem livre para a OpCo depois da reserva | B39: € | C39: =INDEX(Motor!$C$46:$G$46,1,$D$3)*$C$8-C38 -> -3958.9836 | E39: =INDEX(Motor!$C$356:$G$356,1,$D$3)*$E$8-E38 -> 4859.9001 | G39: =INDEX(Motor!$C$666:$G$666,1,$D$3)*$G$8-G38 -> 10587.018 | I39: =INDEX(Motor!$C$976:$G$976,1,$D$3)*$I$8-I38 -> 8531.6767
A40: Memo: KYC/KYB e screening das contrapartes do lote (no custo fixo de tecnologia) | B40: € | C40: =$C$8/(Pressupostos!$C$73*1000)*(Pressupostos!$C$119+12*Pressupostos!$C$120) -> 1268.2927 | E40: =$E$8/(Pressupostos!$C$73*1000)*(Pressupostos!$C$119+12*Pressupostos!$C$120) -> 1268.2927 | G40: =$G$8/(Pressupostos!$C$73*1000)*(Pressupostos!$C$119+12*Pressupostos!$C$120) -> 1268.2927 | I40: =$I$8/(Pressupostos!$C$73*1000)*(Pressupostos!$C$119+12*Pressupostos!$C$120) -> 1268.2927
A41: Memo: custo nocional do capital próprio (8%/ano; fora do EBITDA) | B41: € | C41: =Pressupostos!$C$111*(1-INDEX(Pressupostos!$C$276:$G$276,1,$D$3))*(INDEX(Motor!$C$27:$G$27,1,$D$3)+INDEX(Motor!$C$30:$G$30,1,$D$3))*(INDEX(Motor!$C$33:$G$33,1,$D$3)+INDEX(Motor!$C$34:$G$34,1,$D$3)-Pressupostos!$C$70)/365*$C$8 -> 538.52055 | E41: =Pressupostos!$C$111*(1-INDEX(Pressupostos!$C$277:$G$277,1,$D$3))*(INDEX(Motor!$C$337:$G$337,1,$D$3)+INDEX(Motor!$C$340:$G$340,1,$D$3))*(INDEX(Motor!$C$343:$G$343,1,$D$3)+INDEX(Motor!$C$344:$G$344,1,$D$3)-Pressupostos!$C$70)/365*$E$8 -> 90.958904 | G41: =Pressupostos!$C$111*(1-INDEX(Pressupostos!$C$278:$G$278,1,$D$3))*(INDEX(Motor!$C$647:$G$647,1,$D$3)+INDEX(Motor!$C$650:$G$650,1,$D$3))*(INDEX(Motor!$C$653:$G$653,1,$D$3)+INDEX(Motor!$C$654:$G$654,1,$D$3)-Pressupostos!$C$70)/365*$G$8 -> 80.876712 | I41: =Pressupostos!$C$111*(1-INDEX(Pressupostos!$C$279:$G$279,1,$D$3))*(INDEX(Motor!$C$957:$G$957,1,$D$3)+INDEX(Motor!$C$960:$G$960,1,$D$3))*(INDEX(Motor!$C$963:$G$963,1,$D$3)+INDEX(Motor!$C$964:$G$964,1,$D$3)-Pressupostos!$C$70)/365*$I$8 -> 92.054795
...

Sheet Volumes
A1: Volumes
A2: Volumes físicos por mercadoria e canal, clientes e carteira de terceiros (cenário ativo).
A3: ="Cenário ativo: "&Pressupostos!$C$4&" · euros correntes, sem IVA" -> Cenário ativo: Base · euros correntes, sem IVA
A4: Rubrica | B4: Unidade | C4: 2027 | D4: 2028 | E4: 2029 | F4: 2030 | G4: 2031 | H4: Notas
A5: Calendário
A6: Ano | C6: 2027 | D6: 2028 | E6: 2029 | F6: 2030 | G6: 2031
A8: Azeite (t)
A9: Clientes HoReCa/gourmet ativos (média anual) | B9: n.º | C9: =Pressupostos!$C$211 -> 40 | D9: =Pressupostos!$D$211 -> 180 | E9: =Pressupostos!$E$211 -> 650 | F9: =Pressupostos!$F$211 -> 1300 | G9: =Pressupostos!$G$211 -> 2000
A10: Azeite HoReCa/gourmet | B10: t | C10: =Pressupostos!$C$217 -> 8 | D10: =Pressupostos!$D$217 -> 37 | E10: =Pressupostos!$E$217 -> 133 | F10: =Pressupostos!$F$217 -> 267 | G10: =Pressupostos!$G$217 -> 410
A11: Azeite distribuidores/exportação (offtake) | B11: t | C11: =Pressupostos!$C$223 -> 52 | D11: =Pressupostos!$D$223 -> 363 | E11: =Pressupostos!$E$223 -> 717 | F11: =Pressupostos!$F$223 -> 1183 | G11: =Pressupostos!$G$223 -> 1790
A12: Azeite granel certificado | B12: t | C12: =Pressupostos!$C$229 -> 0 | D12: =Pressupostos!$D$229 -> 0 | E12: =Pressupostos!$E$229 -> 0 | F12: =Pressupostos!$F$229 -> 0 | G12: =Pressupostos!$G$229 -> 0
A13: Azeite total | B13: t | C13: =C10+C11+C12 -> 60 | D13: =D10+D11+D12 -> 400 | E13: =E10+E11+E12 -> 850 | F13: =F10+F11+F12 -> 1450 | G13: =G10+G11+G12 -> 2200
A14: Peso da HoReCa/gourmet no volume | B14: % | C14: =IF(C13>0,C10/C13,0) -> 0.13333333 | D14: =IF(D13>0,D10/D13,0) -> 0.0925 | E14: =IF(E13>0,E10/E13,0) -> 0.15647059 | F14: =IF(F13>0,F10/F13,0) -> 0.18413793 | G14: =IF(G13>0,G10/G13,0) -> 0.18636364
A15: Quota da produção portuguesa | B15: % | C15: =C13/(Pressupostos!$C$74*1000) -> 0.00034285714 | D15: =D13/(Pressupostos!$C$74*1000) -> 0.0022857143 | E15: =E13/(Pressupostos!$C$74*1000) -> 0.0048571429 | F15: =F13/(Pressupostos!$C$74*1000) -> 0.0082857143 | G15: =G13/(Pressupostos!$C$74*1000) -> 0.012571429
A16: Lotes-tipo equivalentes | B16: n.º | C16: =C10/Pressupostos!$C$39+C11/Pressupostos!$C$46+C12/Pressupostos!$C$58 -> 2.1333333 | D16: =D10/Pressupostos!$C$39+D11/Pressupostos!$C$46+D12/Pressupostos!$C$58 -> 13.95 | E16: =E10/Pressupostos!$C$39+E11/Pressupostos!$C$46+E12/Pressupostos!$C$58 -> 30.55 | F16: =F10/Pressupostos!$C$39+F11/Pressupostos!$C$46+F12/Pressupostos!$C$58 -> 52.783333 | G16: =G10/Pressupostos!$C$39+G11/Pressupostos!$C$46+G12/Pressupostos!$C$58 -> 80.166667
A18: Água (modelo agente)
A19: Água | B19: paletes | C19: =Pressupostos!$C$255 -> 150 | D19: =Pressupostos!$D$255 -> 600 | E19: =Pressupostos!$E$255 -> 1000 | F19: =Pressupostos!$F$255 -> 1400 | G19: =Pressupostos!$G$255 -> 1800
A20: Água | B20: L | C20: =C19*Pressupostos!$C$76 -> 112500 | D20: =D19*Pressupostos!$C$76 -> 450000 | E20: =E19*Pressupostos!$C$76 -> 750000 | F20: =F19*Pressupostos!$C$76 -> 1050000 | G20: =G19*Pressupostos!$C$76 -> 1350000
A22: Café verde
A23: Café verde (0 antes do ano de início) | B23: t | C23: =IF(C6<Pressupostos!$G$28,0,Pressupostos!$C$261) -> 0 | D23: =IF(D6<Pressupostos!$G$28,0,Pressupostos!$D$261) -> 0 | E23: =IF(E6<Pressupostos!$G$28,0,Pressupostos!$E$261) -> 30 | F23: =IF(F6<Pressupostos!$G$28,0,Pressupostos!$F$261) -> 60 | G23: =IF(G6<Pressupostos!$G$28,0,Pressupostos!$G$261) -> 100
A25: Verificação para terceiros (banco parceiro)
A26: Carteira média financiada pelo banco parceiro | B26: € | C26: =Pressupostos!$C$267 -> 0 | D26: =Pressupostos!$D$267 -> 500000 | E26: =Pressupostos!$E$267 -> 1500000 | F26: =Pressupostos!$F$267 -> 3000000 | G26: =Pressupostos!$G$267 -> 5000000
A27: Azeite verificado para terceiros | B27: t | C27: =C26/(Pressupostos!$C$103*Pressupostos!$C$104)*Pressupostos!$C$100/1000 -> 0 | D27: =D26/(Pressupostos!$C$103*Pressupostos!$C$104)*Pressupostos!$C$100/1000 -> 457.14286 | E27: =E26/(Pressupostos!$C$103*Pressupostos!$C$104)*Pressupostos!$C$100/1000 -> 1371.4286 | F27: =F26/(Pressupostos!$C$103*Pressupostos!$C$104)*Pressupostos!$C$100/1000 -> 2742.8571 | G27: =G26/(Pressupostos!$C$103*Pressupostos!$C$104)*Pressupostos!$C$100/1000 -> 4571.4286

Sheet Receitas
A1: Receitas
A2: Receitas por fluxo, GMV, capital de lotes financiado e margem de contribuição por fluxo (cenário ativo).
A3: ="Cenário ativo: "&Pressupostos!$C$4&" · euros correntes, sem IVA" -> Cenário ativo: Base · euros correntes, sem IVA
A4: Rubrica | B4: Unidade | C4: 2027 | D4: 2028 | E4: 2029 | F4: 2030 | G4: 2031 | H4: Notas
A5: Receitas por fluxo (€)
A6: Vendas de azeite: HoReCa/gourmet | B6: € | C6: =Volumes!C10*1000*Custos!C8 -> 40680 | D6: =Volumes!D10*1000*Custos!D8 -> 188145 | E6: =Volumes!E10*1000*Custos!E8 -> 676305 | F6: =Volumes!F10*1000*Custos!F8 -> 1357695 | G6: =Volumes!G10*1000*Custos!G8 -> 2084850
A7: Vendas de azeite: distribuidores/exportação | B7: € | C7: =Volumes!C11*1000*Custos!C32 -> 226200 | D7: =Volumes!D11*1000*Custos!D32 -> 1579050 | E7: =Volumes!E11*1000*Custos!E32 -> 3118950 | F7: =Volumes!F11*1000*Custos!F32 -> 5146050 | G7: =Volumes!G11*1000*Custos!G32 -> 7786500
A8: Vendas de azeite: granel certificado | B8: € | C8: =Volumes!C12*1000*Custos!C56 -> 0 | D8: =Volumes!D12*1000*Custos!D56 -> 0 | E8: =Volumes!E12*1000*Custos!E56 -> 0 | F8: =Volumes!F12*1000*Custos!F56 -> 0 | G8: =Volumes!G12*1000*Custos!G56 -> 0
A9: Vendas de azeite | B9: € | C9: =C6+C7+C8 -> 266880 | D9: =D6+D7+D8 -> 1767195 | E9: =E6+E7+E8 -> 3795255 | F9: =F6+F7+F8 -> 6503745 | G9: =G6+G7+G8 -> 9871350
A10: Vendas de café verde | B10: € | C10: =Volumes!C23*1000*Pressupostos!$C$91 -> 0 | D10: =Volumes!D23*1000*Pressupostos!$C$91 -> 0 | E10: =Volumes!E23*1000*Pressupostos!$C$91 -> 235500 | F10: =Volumes!F23*1000*Pressupostos!$C$91 -> 471000 | G10: =Volumes!G23*1000*Pressupostos!$C$91 -> 785000
A11: Memo: GMV de água (faturado pelo engarrafador) | B11: € | C11: =Volumes!C20*Pressupostos!$C$78*(1-Pressupostos!$C$79) -> 40500 | D11: =Volumes!D20*Pressupostos!$C$78*(1-Pressupostos!$C$79) -> 162000 | E11: =Volumes!E20*Pressupostos!$C$78*(1-Pressupostos!$C$79) -> 270000 | F11: =Volumes!F20*Pressupostos!$C$78*(1-Pressupostos!$C$79) -> 378000 | G11: =Volumes!G20*Pressupostos!$C$78*(1-Pressupostos!$C$79) -> 486000
A12: Comissões de agente: água | B12: € | C12: =C11*Pressupostos!$G$27 -> 810 | D12: =D11*Pressupostos!$G$27 -> 3240 | E12: =E11*Pressupostos!$G$27 -> 5400 | F12: =F11*Pressupostos!$G$27 -> 7560 | G12: =G11*Pressupostos!$G$27 -> 9720
A13: Comissões de originação e verificação (terceiros) | B13: € | C13: =Volumes!C26*(Pressupostos!$C$99*Pressupostos!$C$100+Pressupostos!$C$101) -> 0 | D13: =Volumes!D26*(Pressupostos!$C$99*Pressupostos!$C$100+Pressupostos!$C$101) -> 10000 | E13: =Volumes!E26*(Pressupostos!$C$99*Pressupostos!$C$100+Pressupostos!$C$101) -> 30000 | F13: =Volumes!F26*(Pressupostos!$C$99*Pressupostos!$C$100+Pressupostos!$C$101) -> 60000 | G13: =Volumes!G26*(Pressupostos!$C$99*Pressupostos!$C$100+Pressupostos!$C$101) -> 100000
A14: Dados e índice | B14: € | C14: =Pressupostos!$C$273 -> 0 | D14: =Pressupostos!$D$273 -> 0 | E14: =Pressupostos!$E$273 -> 0 | F14: =Pressupostos!$F$273 -> 10000 | G14: =Pressupostos!$G$273 -> 30000
A15: Receita total | B15: € | C15: =C9+C10+C12+C13+C14 -> 267690 | D15: =D9+D10+D12+D13+D14 -> 1780435 | E15: =E9+E10+E12+E13+E14 -> 4066155 | F15: =F9+F10+F12+F13+F14 -> 7052305 | G15: =G9+G10+G12+G13+G14 -> 10796070
A17: GMV e capital de lotes (€)
A18: GMV total (azeite + café + água) | B18: € | C18: =C9+C10+C11 -> 307380 | D18: =D9+D10+D11 -> 1929195 | E18: =E9+E10+E11 -> 4300755 | F18: =F9+F10+F11 -> 7352745 | G18: =G9+G10+G11 -> 11142350
A19: Valor de compra dos lotes (granel + embalamento; café verde) | B19: € | C19: =Volumes!C10*1000*(Custos!C6+Custos!C9)+Volumes!C11*1000*(Custos!C30+Custos!C33)+Volumes!C12*1000*(Custos!C54+Custos!C57)+Volumes!C23*1000*Pressupostos!$C$90 -> 243800 | D19: =Volumes!D10*1000*(Custos!D6+Custos!D9)+Volumes!D11*1000*(Custos!D30+Custos!D33)+Volumes!D12*1000*(Custos!D54+Custos!D57)+Volumes!D23*1000*Pressupostos!$C$90 -> 1623700 | E19: =Volumes!E10*1000*(Custos!E6+Custos!E9)+Volumes!E11*1000*(Custos!E30+Custos!E33)+Volumes!E12*1000*(Custos!E54+Custos!E57)+Volumes!E23*1000*Pressupostos!$C$90 -> 3665800 | F19: =Volumes!F10*1000*(Custos!F6+Custos!F9)+Volumes!F11*1000*(Custos!F30+Custos!F33)+Volumes!F12*1000*(Custos!F54+Custos!F57)+Volumes!F23*1000*Pressupostos!$C$90 -> 6319200 | G19: =Volumes!G10*1000*(Custos!G6+Custos!G9)+Volumes!G11*1000*(Custos!G30+Custos!G33)+Volumes!G12*1000*(Custos!G54+Custos!G57)+Volumes!G23*1000*Pressupostos!$C$90 -> 9651000
A20: dos quais financiados por obrigações (capital financiado) | B20: € | C20: =C19*Pressupostos!$C$280 -> 0 | D20: =D19*Pressupostos!$D$280 -> 1461330 | E20: =E19*Pressupostos!$E$280 -> 3299220 | F20: =F19*Pressupostos!$F$280 -> 5687280 | G20: =G19*Pressupostos!$G$280 -> 8685900
A22: Margem de contribuição por fluxo (€)
A23: Azeite: HoReCa/gourmet | B23: € | C23: =Volumes!C10*1000*Custos!C25 -> 2727.5145 | D23: =Volumes!D10*1000*Custos!D25 -> 5610.3505 | E23: =Volumes!E10*1000*Custos!E25 -> 46169.051 | F23: =Volumes!F10*1000*Custos!F25 -> 96209.043 | G23: =Volumes!G10*1000*Custos!G25 -> 147736.73
A24: Azeite: distribuidores/exportação | B24: € | C24: =Volumes!C11*1000*Custos!C49 -> 5010.6274 | D24: =Volumes!D11*1000*Custos!D49 -> 18665.41 | E24: =Volumes!E11*1000*Custos!E49 -> 46051.842 | F24: =Volumes!F11*1000*Custos!F49 -> 79304.957 | G24: =Volumes!G11*1000*Custos!G49 -> 119996.51
A25: Azeite: granel certificado | B25: € | C25: =Volumes!C12*1000*Custos!C73 -> 0 | D25: =Volumes!D12*1000*Custos!D73 -> 0 | E25: =Volumes!E12*1000*Custos!E73 -> 0 | F25: =Volumes!F12*1000*Custos!F73 -> 0 | G25: =Volumes!G12*1000*Custos!G73 -> 0
A26: Azeite | B26: € | C26: =C23+C24+C25 -> 7738.1419 | D26: =D23+D24+D25 -> 24275.761 | E26: =E23+E24+E25 -> 92220.893 | F26: =F23+F24+F25 -> 175514 | G26: =G23+G24+G25 -> 267733.24
A27: Margem média do azeite | B27: €/kg | C27: =IF(Volumes!C13>0,C26/(Volumes!C13*1000),0) -> 0.12896903 | D27: =IF(Volumes!D13>0,D26/(Volumes!D13*1000),0) -> 0.060689402 | E27: =IF(Volumes!E13>0,E26/(Volumes!E13*1000),0) -> 0.10849517 | F27: =IF(Volumes!F13>0,F26/(Volumes!F13*1000),0) -> 0.12104414 | G27: =IF(Volumes!G13>0,G26/(Volumes!G13*1000),0) -> 0.12169693
A28: Margem do azeite em % das vendas de azeite | B28: % | C28: =IF(C9>0,C26/C9,0) -> 0.028994836 | D28: =IF(D9>0,D26/D9,0) -> 0.013736889 | E28: =IF(E9>0,E26/E9,0) -> 0.024298998 | F28: =IF(F9>0,F26/F9,0) -> 0.026986605 | G28: =IF(G9>0,G26/G9,0) -> 0.027122252
A29: Café: cupão por kg | B29: €/kg | C29: =Pressupostos!$C$286*Pressupostos!$C$90*(Pressupostos!$C$93+Pressupostos!$C$94-Pressupostos!$C$95)/365*Pressupostos!$C$280/Pressupostos!$G$31 -> 0 | D29: =Pressupostos!$D$286*Pressupostos!$C$90*(Pressupostos!$C$93+Pressupostos!$C$94-Pressupostos!$C$95)/365*Pressupostos!$D$280/Pressupostos!$G$31 -> 0.077671233 | E29: =Pressupostos!$E$286*Pressupostos!$C$90*(Pressupostos!$C$93+Pressupostos!$C$94-Pressupostos!$C$95)/365*Pressupostos!$E$280/Pressupostos!$G$31 -> 0.072816781 | F29: =Pressupostos!$F$286*Pressupostos!$C$90*(Pressupostos!$C$93+Pressupostos!$C$94-Pressupostos!$C$95)/365*Pressupostos!$F$280/Pressupostos!$G$31 -> 0.067962329 | G29: =Pressupostos!$G$286*Pressupostos!$C$90*(Pressupostos!$C$93+Pressupostos!$C$94-Pressupostos!$C$95)/365*Pressupostos!$G$280/Pressupostos!$G$31 -> 0.067962329
A30: Café verde | B30: € | C30: =Volumes!C23*1000*(Pressupostos!$C$91-Pressupostos!$C$90-Pressupostos!$C$92-C29-Pressupostos!$C$96*Pressupostos!$C$91-Pressupostos!$C$97-Pressupostos!$G$29*Pressupostos!$C$90) -> 0 | D30: =Volumes!D23*1000*(Pressupostos!$C$91-Pressupostos!$C$90-Pressupostos!$C$92-D29-Pressupostos!$C$96*Pressupostos!$C$91-Pressupostos!$C$97-Pressupostos!$G$29*Pressupostos!$C$90) -> 0 | E30: =Volumes!E23*1000*(Pressupostos!$C$91-Pressupostos!$C$90-Pressupostos!$C$92-E29-Pressupostos!$C$96*Pressupostos!$C$91-Pressupostos!$C$97-Pressupostos!$G$29*Pressupostos!$C$90) -> 16502.497 | F30: =Volumes!F23*1000*(Pressupostos!$C$91-Pressupostos!$C$90-Pressupostos!$C$92-F29-Pressupostos!$C$96*Pressupostos!$C$91-Pressupostos!$C$97-Pressupostos!$G$29*Pressupostos!$C$90) -> 33296.26 | G30: =Volumes!G23*1000*(Pressupostos!$C$91-Pressupostos!$C$90-Pressupostos!$C$92-G29-Pressupostos!$C$96*Pressupostos!$C$91-Pressupostos!$C$97-Pressupostos!$G$29*Pressupostos!$C$90) -> 55493.767
A31: Água (comissão) | B31: € | C31: =C12 -> 810 | D31: =D12 -> 3240 | E31: =E12 -> 5400 | F31: =F12 -> 7560 | G31: =G12 -> 9720
A32: Verificação para terceiros (líquida) | B32: € | C32: =C13-Custos!C89 -> 0 | D32: =D13-Custos!D89 -> 1771.4286 | E32: =E13-Custos!E89 -> 5314.2857 | F32: =F13-Custos!F89 -> 10628.571 | G32: =G13-Custos!G89 -> 17714.286
A33: Dados e índice | B33: € | C33: =C14 -> 0 | D33: =D14 -> 0 | E33: =E14 -> 0 | F33: =F14 -> 10000 | G33: =G14 -> 30000
A34: Margem de contribuição total | B34: € | C34: =C26+C30+C31+C32+C33 -> 8548.1419 | D34: =D26+D30+D31+D32+D33 -> 29287.189 | E34: =E26+E30+E31+E32+E33 -> 119437.67 | F34: =F26+F30+F31+F32+F33 -> 236998.83 | G34: =G26+G30+G31+G32+G33 -> 380661.3

Sheet Pessoal
A1: Pessoal
A2: Equipa por função; salário bruto anual com 14 meses, TSU de 23,75% + 2% e subsídio de refeição (cenário ativo).
A3: ="Cenário ativo: "&Pressupostos!$C$4&" · euros correntes, sem IVA" -> Cenário ativo: Base · euros correntes, sem IVA
A4: Rubrica | B4: Unidade | C4: 2027 | D4: 2028 | E4: 2029 | F4: 2030 | G4: 2031 | H4: Notas
A5: FTE por função
A6: CEO / comercial (fundador) | B6: FTE | C6: =Pressupostos!$C$318 -> 1 | D6: =Pressupostos!$D$318 -> 1 | E6: =Pressupostos!$E$318 -> 1 | F6: =Pressupostos!$F$318 -> 1 | G6: =Pressupostos!$G$318 -> 1
A7: CTO (fundador) | B7: FTE | C7: =Pressupostos!$C$324 -> 1 | D7: =Pressupostos!$D$324 -> 1 | E7: =Pressupostos!$E$324 -> 1 | F7: =Pressupostos!$F$324 -> 1 | G7: =Pressupostos!$G$324 -> 1
A8: Engenheiro(a) de software | B8: FTE | C8: =Pressupostos!$C$330 -> 1 | D8: =Pressupostos!$D$330 -> 1 | E8: =Pressupostos!$E$330 -> 2 | F8: =Pressupostos!$F$330 -> 2 | G8: =Pressupostos!$G$330 -> 2
A9: Responsável de Risco e Tesouraria | B9: FTE | C9: =Pressupostos!$C$336 -> 1 | D9: =Pressupostos!$D$336 -> 1 | E9: =Pressupostos!$E$336 -> 1 | F9: =Pressupostos!$F$336 -> 1 | G9: =Pressupostos!$G$336 -> 1
A10: Compliance / AML | B10: FTE | C10: =Pressupostos!$C$342 -> 0.5 | D10: =Pressupostos!$D$342 -> 1 | E10: =Pressupostos!$E$342 -> 1 | F10: =Pressupostos!$F$342 -> 1 | G10: =Pressupostos!$G$342 -> 1
A11: Operações e supply | B11: FTE | C11: =Pressupostos!$C$348 -> 1 | D11: =Pressupostos!$D$348 -> 1 | E11: =Pressupostos!$E$348 -> 1 | F11: =Pressupostos!$F$348 -> 2 | G11: =Pressupostos!$G$348 -> 2
A12: Técnico(a) de qualidade do azeite | B12: FTE | C12: =Pressupostos!$C$354 -> 0.5 | D12: =Pressupostos!$D$354 -> 1 | E12: =Pressupostos!$E$354 -> 1 | F12: =Pressupostos!$F$354 -> 1 | G12: =Pressupostos!$G$354 -> 1
A13: Gestor(a) de conta B2B (~400 contas) | B13: FTE | C13: =Pressupostos!$C$360 -> 1 | D13: =Pressupostos!$D$360 -> 1 | E13: =Pressupostos!$E$360 -> 2 | F13: =Pressupostos!$F$360 -> 3 | G13: =Pressupostos!$G$360 -> 5
A14: Controller financeiro | B14: FTE | C14: =Pressupostos!$C$366 -> 0 | D14: =Pressupostos!$D$366 -> 0 | E14: =Pressupostos!$E$366 -> 0 | F14: =Pressupostos!$F$366 -> 1 | G14: =Pressupostos!$G$366 -> 1
A15: Analista de dados/produto | B15: FTE | C15: =Pressupostos!$C$372 -> 0 | D15: =Pressupostos!$D$372 -> 0 | E15: =Pressupostos!$E$372 -> 0 | F15: =Pressupostos!$F$372 -> 0 | G15: =Pressupostos!$G$372 -> 1
A16: Assistente de operações | B16: FTE | C16: =Pressupostos!$C$378 -> 0 | D16: =Pressupostos!$D$378 -> 0 | E16: =Pressupostos!$E$378 -> 1 | F16: =Pressupostos!$F$378 -> 1 | G16: =Pressupostos!$G$378 -> 1
A17: Trader de granel e exportação | B17: FTE | C17: =Pressupostos!$C$384 -> 0 | D17: =Pressupostos!$D$384 -> 0 | E17: =Pressupostos!$E$384 -> 0 | F17: =Pressupostos!$F$384 -> 0 | G17: =Pressupostos!$G$384 -> 0
A18: Total de FTE | B18: FTE | C18: =C6+C7+C8+C9+C10+C11+C12+C13+C14+C15+C16+C17 -> 7 | D18: =D6+D7+D8+D9+D10+D11+D12+D13+D14+D15+D16+D17 -> 8 | E18: =E6+E7+E8+E9+E10+E11+E12+E13+E14+E15+E16+E17 -> 11 | F18: =F6+F7+F8+F9+F10+F11+F12+F13+F14+F15+F16+F17 -> 14 | G18: =G6+G7+G8+G9+G10+G11+G12+G13+G14+G15+G16+G17 -> 17
A20: Custo salarial bruto (€, 14 meses, com variável e atualização)
A21: CEO / comercial (fundador) | B21: € | C21: =C6*Pressupostos!$C$129*(1+Pressupostos!$C$125)^0*(1+Pressupostos!$C$130)*Pressupostos!$C$126 -> 43998 | D21: =D6*Pressupostos!$C$129*(1+Pressupostos!$C$125)^1*(1+Pressupostos!$C$130) -> 61800 | E21: =E6*Pressupostos!$C$129*(1+Pressupostos!$C$125)^2*(1+Pressupostos!$C$130) -> 63654 | F21: =F6*Pressupostos!$C$129*(1+Pressupostos!$C$125)^3*(1+Pressupostos!$C$130) -> 65563.62 | G21: =G6*Pressupostos!$C$129*(1+Pressupostos!$C$125)^4*(1+Pressupostos!$C$130) -> 67530.529
A22: CTO (fundador) | B22: € | C22: =C7*Pressupostos!$C$131*(1+Pressupostos!$C$125)^0*(1+Pressupostos!$C$132)*Pressupostos!$C$126 -> 47664.5 | D22: =D7*Pressupostos!$C$131*(1+Pressupostos!$C$125)^1*(1+Pressupostos!$C$132) -> 66950 | E22: =E7*Pressupostos!$C$131*(1+Pressupostos!$C$125)^2*(1+Pressupostos!$C$132) -> 68958.5 | F22: =F7*Pressupostos!$C$131*(1+Pressupostos!$C$125)^3*(1+Pressupostos!$C$132) -> 71027.255 | G22: =G7*Pressupostos!$C$131*(1+Pressupostos!$C$125)^4*(1+Pressupostos!$C$132) -> 73158.073
A23: Engenheiro(a) de software | B23: € | C23: =C8*Pressupostos!$C$133*(1+Pressupostos!$C$125)^0*(1+Pressupostos!$C$134) -> 45000 | D23: =D8*Pressupostos!$C$133*(1+Pressupostos!$C$125)^1*(1+Pressupostos!$C$134) -> 46350 | E23: =E8*Pressupostos!$C$133*(1+Pressupostos!$C$125)^2*(1+Pressupostos!$C$134) -> 95481 | F23: =F8*Pressupostos!$C$133*(1+Pressupostos!$C$125)^3*(1+Pressupostos!$C$134) -> 98345.43 | G23: =G8*Pressupostos!$C$133*(1+Pressupostos!$C$125)^4*(1+Pressupostos!$C$134) -> 101295.79
A24: Responsável de Risco e Tesouraria | B24: € | C24: =C9*Pressupostos!$C$135*(1+Pressupostos!$C$125)^0*(1+Pressupostos!$C$136) -> 60000 | D24: =D9*Pressupostos!$C$135*(1+Pressupostos!$C$125)^1*(1+Pressupostos!$C$136) -> 61800 | E24: =E9*Pressupostos!$C$135*(1+Pressupostos!$C$125)^2*(1+Pressupostos!$C$136) -> 63654 | F24: =F9*Pressupostos!$C$135*(1+Pressupostos!$C$125)^3*(1+Pressupostos!$C$136) -> 65563.62 | G24: =G9*Pressupostos!$C$135*(1+Pressupostos!$C$125)^4*(1+Pressupostos!$C$136) -> 67530.529
A25: Compliance / AML | B25: € | C25: =C10*Pressupostos!$C$137*(1+Pressupostos!$C$125)^0*(1+Pressupostos!$C$138) -> 22500 | D25: =D10*Pressupostos!$C$137*(1+Pressupostos!$C$125)^1*(1+Pressupostos!$C$138) -> 46350 | E25: =E10*Pressupostos!$C$137*(1+Pressupostos!$C$125)^2*(1+Pressupostos!$C$138) -> 47740.5 | F25: =F10*Pressupostos!$C$137*(1+Pressupostos!$C$125)^3*(1+Pressupostos!$C$138) -> 49172.715 | G25: =G10*Pressupostos!$C$137*(1+Pressupostos!$C$125)^4*(1+Pressupostos!$C$138) -> 50647.896
A26: Operações e supply | B26: € | C26: =C11*Pressupostos!$C$139*(1+Pressupostos!$C$125)^0*(1+Pressupostos!$C$140) -> 38000 | D26: =D11*Pressupostos!$C$139*(1+Pressupostos!$C$125)^1*(1+Pressupostos!$C$140) -> 39140 | E26: =E11*Pressupostos!$C$139*(1+Pressupostos!$C$125)^2*(1+Pressupostos!$C$140) -> 40314.2 | F26: =F11*Pressupostos!$C$139*(1+Pressupostos!$C$125)^3*(1+Pressupostos!$C$140) -> 83047.252 | G26: =G11*Pressupostos!$C$139*(1+Pressupostos!$C$125)^4*(1+Pressupostos!$C$140) -> 85538.67
A27: Técnico(a) de qualidade do azeite | B27: € | C27: =C12*Pressupostos!$C$141*(1+Pressupostos!$C$125)^0*(1+Pressupostos!$C$142) -> 16000 | D27: =D12*Pressupostos!$C$141*(1+Pressupostos!$C$125)^1*(1+Pressupostos!$C$142) -> 32960 | E27: =E12*Pressupostos!$C$141*(1+Pressupostos!$C$125)^2*(1+Pressupostos!$C$142) -> 33948.8 | F27: =F12*Pressupostos!$C$141*(1+Pressupostos!$C$125)^3*(1+Pressupostos!$C$142) -> 34967.264 | G27: =G12*Pressupostos!$C$141*(1+Pressupostos!$C$125)^4*(1+Pressupostos!$C$142) -> 36016.282
A28: Gestor(a) de conta B2B (~400 contas) | B28: € | C28: =C13*Pressupostos!$C$143*(1+Pressupostos!$C$125)^0*(1+Pressupostos!$C$144) -> 34500 | D28: =D13*Pressupostos!$C$143*(1+Pressupostos!$C$125)^1*(1+Pressupostos!$C$144) -> 35535 | E28: =E13*Pressupostos!$C$143*(1+Pressupostos!$C$125)^2*(1+Pressupostos!$C$144) -> 73202.1 | F28: =F13*Pressupostos!$C$143*(1+Pressupostos!$C$125)^3*(1+Pressupostos!$C$144) -> 113097.24 | G28: =G13*Pressupostos!$C$143*(1+Pressupostos!$C$125)^4*(1+Pressupostos!$C$144) -> 194150.27
A29: Controller financeiro | B29: € | C29: =C14*Pressupostos!$C$145*(1+Pressupostos!$C$125)^0*(1+Pressupostos!$C$146) -> 0 | D29: =D14*Pressupostos!$C$145*(1+Pressupostos!$C$125)^1*(1+Pressupostos!$C$146) -> 0 | E29: =E14*Pressupostos!$C$145*(1+Pressupostos!$C$125)^2*(1+Pressupostos!$C$146) -> 0 | F29: =F14*Pressupostos!$C$145*(1+Pressupostos!$C$125)^3*(1+Pressupostos!$C$146) -> 49172.715 | G29: =G14*Pressupostos!$C$145*(1+Pressupostos!$C$125)^4*(1+Pressupostos!$C$146) -> 50647.896
A30: Analista de dados/produto | B30: € | C30: =C15*Pressupostos!$C$147*(1+Pressupostos!$C$125)^0*(1+Pressupostos!$C$148) -> 0 | D30: =D15*Pressupostos!$C$147*(1+Pressupostos!$C$125)^1*(1+Pressupostos!$C$148) -> 0 | E30: =E15*Pressupostos!$C$147*(1+Pressupostos!$C$125)^2*(1+Pressupostos!$C$148) -> 0 | F30: =F15*Pressupostos!$C$147*(1+Pressupostos!$C$125)^3*(1+Pressupostos!$C$148) -> 0 | G30: =G15*Pressupostos!$C$147*(1+Pressupostos!$C$125)^4*(1+Pressupostos!$C$148) -> 45020.352
A31: Assistente de operações | B31: € | C31: =C16*Pressupostos!$C$149*(1+Pressupostos!$C$125)^0*(1+Pressupostos!$C$150) -> 0 | D31: =D16*Pressupostos!$C$149*(1+Pressupostos!$C$125)^1*(1+Pressupostos!$C$150) -> 0 | E31: =E16*Pressupostos!$C$149*(1+Pressupostos!$C$125)^2*(1+Pressupostos!$C$150) -> 25461.6 | F31: =F16*Pressupostos!$C$149*(1+Pressupostos!$C$125)^3*(1+Pressupostos!$C$150) -> 26225.448 | G31: =G16*Pressupostos!$C$149*(1+Pressupostos!$C$125)^4*(1+Pressupostos!$C$150) -> 27012.211
A32: Trader de granel e exportação | B32: € | C32: =C17*Pressupostos!$C$151*(1+Pressupostos!$C$125)^0*(1+Pressupostos!$C$152) -> 0 | D32: =D17*Pressupostos!$C$151*(1+Pressupostos!$C$125)^1*(1+Pressupostos!$C$152) -> 0 | E32: =E17*Pressupostos!$C$151*(1+Pressupostos!$C$125)^2*(1+Pressupostos!$C$152) -> 0 | F32: =F17*Pressupostos!$C$151*(1+Pressupostos!$C$125)^3*(1+Pressupostos!$C$152) -> 0 | G32: =G17*Pressupostos!$C$151*(1+Pressupostos!$C$125)^4*(1+Pressupostos!$C$152) -> 0
A33: Salários brutos | B33: € | C33: =C21+C22+C23+C24+C25+C26+C27+C28+C29+C30+C31+C32 -> 307662.5 | D33: =D21+D22+D23+D24+D25+D26+D27+D28+D29+D30+D31+D32 -> 390885 | E33: =E21+E22+E23+E24+E25+E26+E27+E28+E29+E30+E31+E32 -> 512414.7 | F33: =F21+F22+F23+F24+F25+F26+F27+F28+F29+F30+F31+F32 -> 656182.56 | G33: =G21+G22+G23+G24+G25+G26+G27+G28+G29+G30+G31+G32 -> 798548.5
A34: TSU e outros encargos | B34: € | C34: =C33*(Pressupostos!$C$122+Pressupostos!$C$123) -> 79223.094 | D34: =D33*(Pressupostos!$C$122+Pressupostos!$C$123) -> 100652.89 | E34: =E33*(Pressupostos!$C$122+Pressupostos!$C$123) -> 131946.79 | F34: =F33*(Pressupostos!$C$122+Pressupostos!$C$123) -> 168967.01 | G34: =G33*(Pressupostos!$C$122+Pressupostos!$C$123) -> 205626.24
A35: Subsídio de refeição | B35: € | C35: =C18*Pressupostos!$C$124*(1+Pressupostos!$C$125)^0 -> 14000 | D35: =D18*Pressupostos!$C$124*(1+Pressupostos!$C$125)^1 -> 16480 | E35: =E18*Pressupostos!$C$124*(1+Pressupostos!$C$125)^2 -> 23339.8 | F35: =F18*Pressupostos!$C$124*(1+Pressupostos!$C$125)^3 -> 30596.356 | G35: =G18*Pressupostos!$C$124*(1+Pressupostos!$C$125)^4 -> 38267.3
A36: Custo total com pessoal | B36: € | C36: =C33+C34+C35 -> 400885.59 | D36: =D33+D34+D35 -> 508017.89 | E36: =E33+E34+E35 -> 667701.29 | F36: =F33+F34+F35 -> 855745.93 | G36: =G33+G34+G35 -> 1042442
A37: Custo médio por FTE | B37: € | C37: =IF(C18>0,C36/C18,0) -> 57269.371 | D37: =IF(D18>0,D36/D18,0) -> 63502.236 | E37: =IF(E18>0,E36/E18,0) -> 60700.117 | F37: =IF(F18>0,F36/F18,0) -> 61124.709 | G37: =IF(G18>0,G36/G18,0) -> 61320.12
A39: Tabela salarial (inputs em Pressupostos; valores de 2027)
A40: Função | B40: Fundador? | C40: Salário anual (14 meses) | D40: Salário mensal (÷ 14) | E40: Variável | F40: Custo anual c/ encargos (1 FTE)
A41: CEO / comercial (fundador) | B41: sim (60% até ao gate) | C41: =Pressupostos!$C$129 -> 60000 | D41: =C41/14 -> 4285.7143 | E41: =Pressupostos!$C$130 -> 0 | F41: =C41*(1+E41)*(1+Pressupostos!$C$122+Pressupostos!$C$123)+Pressupostos!$C$124 -> 77450
A42: CTO (fundador) | B42: sim (60% até ao gate) | C42: =Pressupostos!$C$131 -> 65000 | D42: =C42/14 -> 4642.8571 | E42: =Pressupostos!$C$132 -> 0 | F42: =C42*(1+E42)*(1+Pressupostos!$C$122+Pressupostos!$C$123)+Pressupostos!$C$124 -> 83737.5
...

Sheet Custos
A1: Custos
A2: Economia por kg de cada canal, custos diretos, opex não salarial, capex e amortizações (cenário ativo).
A3: ="Cenário ativo: "&Pressupostos!$C$4&" · euros correntes, sem IVA" -> Cenário ativo: Base · euros correntes, sem IVA
A4: Rubrica | B4: Unidade | C4: 2027 | D4: 2028 | E4: 2029 | F4: 2030 | G4: 2031 | H4: Notas
A5: Economia por kg: HoReCa/gourmet
A6: Preço ao produtor (índice + prémio de origem) | B6: €/kg | C6: =Pressupostos!$G$10+Pressupostos!$G$11 -> 3.6 | D6: =Pressupostos!$G$10+Pressupostos!$G$11 -> 3.6 | E6: =Pressupostos!$G$10+Pressupostos!$G$11 -> 3.6 | F6: =Pressupostos!$G$10+Pressupostos!$G$11 -> 3.6 | G6: =Pressupostos!$G$10+Pressupostos!$G$11 -> 3.6
A7: Preço de referência do comprador | B7: €/kg | C7: =Pressupostos!$G$15 -> 5.65 | D7: =Pressupostos!$G$15 -> 5.65 | E7: =Pressupostos!$G$15 -> 5.65 | F7: =Pressupostos!$G$15 -> 5.65 | G7: =Pressupostos!$G$15 -> 5.65
A8: Preço de venda Sprout (referência − desconto) | B8: €/kg | C8: =C7*(1-Pressupostos!$G$16) -> 5.085 | D8: =D7*(1-Pressupostos!$G$16) -> 5.085 | E8: =E7*(1-Pressupostos!$G$16) -> 5.085 | F8: =F7*(1-Pressupostos!$G$16) -> 5.085 | G8: =G7*(1-Pressupostos!$G$16) -> 5.085
A9: Embalamento | B9: €/kg | C9: =Pressupostos!$C$37 -> 0.55 | D9: =Pressupostos!$C$37 -> 0.55 | E9: =Pressupostos!$C$37 -> 0.55 | F9: =Pressupostos!$C$37 -> 0.55 | G9: =Pressupostos!$C$37 -> 0.55
A10: Logística | B10: €/kg | C10: =Pressupostos!$C$236 -> 0.3 | D10: =Pressupostos!$D$236 -> 0.3 | E10: =Pressupostos!$E$236 -> 0.28 | F10: =Pressupostos!$F$236 -> 0.27 | G10: =Pressupostos!$G$236 -> 0.27
A11: Armazém logístico (3PL) e picking | B11: €/kg | C11: =Pressupostos!$C$38 -> 0.06 | D11: =Pressupostos!$C$38 -> 0.06 | E11: =Pressupostos!$C$38 -> 0.06 | F11: =Pressupostos!$C$38 -> 0.06 | G11: =Pressupostos!$C$38 -> 0.06
A12: Stock médio | B12: dias | C12: =Pressupostos!$C$242 -> 180 | D12: =Pressupostos!$D$242 -> 180 | E12: =Pressupostos!$E$242 -> 45 | F12: =Pressupostos!$F$242 -> 45 | G12: =Pressupostos!$G$242 -> 45
A13: Prazo médio de recebimento | B13: dias | C13: =Pressupostos!$G$17 -> 35 | D13: =Pressupostos!$G$17 -> 35 | E13: =Pressupostos!$G$17 -> 35 | F13: =Pressupostos!$G$17 -> 35 | G13: =Pressupostos!$G$17 -> 35
A14: Armazenagem | B14: €/kg | C14: =Pressupostos!$C$64*C12/30/1000 -> 0.024 | D14: =Pressupostos!$C$64*D12/30/1000 -> 0.024 | E14: =Pressupostos!$C$64*E12/30/1000 -> 0.006 | F14: =Pressupostos!$C$64*F12/30/1000 -> 0.006 | G14: =Pressupostos!$C$64*G12/30/1000 -> 0.006
A15: Seguro do stock | B15: €/kg | C15: =C6*Pressupostos!$C$65*C12/365 -> 0.0035506849 | D15: =D6*Pressupostos!$C$65*D12/365 -> 0.0035506849 | E15: =E6*Pressupostos!$C$65*E12/365 -> 0.00088767123 | F15: =F6*Pressupostos!$C$65*F12/365 -> 0.00088767123 | G15: =G6*Pressupostos!$C$65*G12/365 -> 0.00088767123
A16: Análises (testes de qualidade) | B16: €/kg | C16: =Pressupostos!$C$40*Pressupostos!$C$66/(Pressupostos!$C$39*1000) -> 0.03 | D16: =Pressupostos!$C$40*Pressupostos!$C$66/(Pressupostos!$C$39*1000) -> 0.03 | E16: =Pressupostos!$C$40*Pressupostos!$C$66/(Pressupostos!$C$39*1000) -> 0.03 | F16: =Pressupostos!$C$40*Pressupostos!$C$66/(Pressupostos!$C$39*1000) -> 0.03 | G16: =Pressupostos!$C$40*Pressupostos!$C$66/(Pressupostos!$C$39*1000) -> 0.03
A17: Perdas físicas | B17: €/kg | C17: =Pressupostos!$C$67*C6 -> 0.018 | D17: =Pressupostos!$C$67*D6 -> 0.018 | E17: =Pressupostos!$C$67*E6 -> 0.018 | F17: =Pressupostos!$C$67*F6 -> 0.018 | G17: =Pressupostos!$C$67*G6 -> 0.018
A18: Desclassificação esperada | B18: €/kg | C18: =Pressupostos!$C$68*Pressupostos!$C$69*C12/90 -> 0.018 | D18: =Pressupostos!$C$68*Pressupostos!$C$69*D12/90 -> 0.018 | E18: =Pressupostos!$C$68*Pressupostos!$C$69*E12/90 -> 0.0045 | F18: =Pressupostos!$C$68*Pressupostos!$C$69*F12/90 -> 0.0045 | G18: =Pressupostos!$C$68*Pressupostos!$C$69*G12/90 -> 0.0045
A19: Custódia (collateral manager) | B19: €/kg | C19: =Pressupostos!$C$41/(Pressupostos!$C$39*1000) -> 0.1 | D19: =Pressupostos!$C$41/(Pressupostos!$C$39*1000) -> 0.1 | E19: =Pressupostos!$C$41/(Pressupostos!$C$39*1000) -> 0.1 | F19: =Pressupostos!$C$41/(Pressupostos!$C$39*1000) -> 0.1 | G19: =Pressupostos!$C$41/(Pressupostos!$C$39*1000) -> 0.1
A20: Pagamentos bancários | B20: €/kg | C20: =Pressupostos!$C$42 -> 0.01 | D20: =Pressupostos!$C$42 -> 0.01 | E20: =Pressupostos!$C$42 -> 0.01 | F20: =Pressupostos!$C$42 -> 0.01 | G20: =Pressupostos!$C$42 -> 0.01
A21: Provisão de crédito | B21: €/kg | C21: =Pressupostos!$G$18*C8 -> 0.03051 | D21: =Pressupostos!$G$18*D8 -> 0.03051 | E21: =Pressupostos!$G$18*E8 -> 0.03051 | F21: =Pressupostos!$G$18*F8 -> 0.03051 | G21: =Pressupostos!$G$18*G8 -> 0.03051
A22: Cobertura de preço explícita (sem futuros de azeite) | B22: €/kg | C22: =Pressupostos!$C$71*C8 -> 0 | D22: =Pressupostos!$C$71*D8 -> 0 | E22: =Pressupostos!$C$71*E8 -> 0 | F22: =Pressupostos!$C$71*F8 -> 0 | G22: =Pressupostos!$C$71*G8 -> 0
A23: Cupão das obrigações (financiamento do stock) | B23: €/kg | C23: =Pressupostos!$C$286*(C6+C9)*(C12+C13-Pressupostos!$C$70)/365*Pressupostos!$C$280/Pressupostos!$G$31 -> 0 | D23: =Pressupostos!$D$286*(D6+D9)*(D12+D13-Pressupostos!$C$70)/365*Pressupostos!$D$280/Pressupostos!$G$31 -> 0.18930822 | E23: =Pressupostos!$E$286*(E6+E9)*(E12+E13-Pressupostos!$C$70)/365*Pressupostos!$E$280/Pressupostos!$G$31 -> 0.04796661 | F23: =Pressupostos!$F$286*(F6+F9)*(F12+F13-Pressupostos!$C$70)/365*Pressupostos!$F$280/Pressupostos!$G$31 -> 0.044768836 | G23: =Pressupostos!$G$286*(G6+G9)*(G12+G13-Pressupostos!$C$70)/365*Pressupostos!$G$280/Pressupostos!$G$31 -> 0.044768836
A24: Custo direto total | B24: €/kg | C24: =C6+C9+C10+C11+C14+C15+C16+C17+C18+C19+C20+C21+C22+C23 -> 4.7440607 | D24: =D6+D9+D10+D11+D14+D15+D16+D17+D18+D19+D20+D21+D22+D23 -> 4.9333689 | E24: =E6+E9+E10+E11+E14+E15+E16+E17+E18+E19+E20+E21+E22+E23 -> 4.7378643 | F24: =F6+F9+F10+F11+F14+F15+F16+F17+F18+F19+F20+F21+F22+F23 -> 4.7246665 | G24: =G6+G9+G10+G11+G14+G15+G16+G17+G18+G19+G20+G21+G22+G23 -> 4.7246665
A25: Margem de contribuição | B25: €/kg | C25: =C8-C24 -> 0.34093932 | D25: =D8-D24 -> 0.1516311 | E25: =E8-E24 -> 0.34713572 | F25: =F8-F24 -> 0.36033349 | G25: =G8-G24 -> 0.36033349
A26: Margem de contribuição em % do preço | B26: % | C26: =IF(C8>0,C25/C8,0) -> 0.067048046 | D26: =IF(D8>0,D25/D8,0) -> 0.029819291 | E26: =IF(E8>0,E25/E8,0) -> 0.068266611 | F26: =IF(F8>0,F25/F8,0) -> 0.070862044 | G26: =IF(G8>0,G25/G8,0) -> 0.070862044
A27: Capital de giro por kg vendido | B27: €/kg | C27: =(C6+C9)*(C12-Pressupostos!$C$70)/365+C8*C13/365 -> 2.1930822 | D27: =(D6+D9)*(D12-Pressupostos!$C$70)/365+D8*D13/365 -> 2.1930822 | E27: =(E6+E9)*(E12-Pressupostos!$C$70)/365+E8*E13/365 -> 0.65815068 | F27: =(F6+F9)*(F12-Pressupostos!$C$70)/365+F8*F13/365 -> 0.65815068 | G27: =(G6+G9)*(G12-Pressupostos!$C$70)/365+G8*G13/365 -> 0.65815068
A29: Economia por kg: distribuidores/exportação
A30: Preço ao produtor (índice + prémio de origem) | B30: €/kg | C30: =Pressupostos!$G$10+Pressupostos!$G$12 -> 3.6 | D30: =Pressupostos!$G$10+Pressupostos!$G$12 -> 3.6 | E30: =Pressupostos!$G$10+Pressupostos!$G$12 -> 3.6 | F30: =Pressupostos!$G$10+Pressupostos!$G$12 -> 3.6 | G30: =Pressupostos!$G$10+Pressupostos!$G$12 -> 3.6
A31: Preço de referência do comprador | B31: €/kg | C31: =Pressupostos!$G$20+Pressupostos!$G$21 -> 4.35 | D31: =Pressupostos!$G$20+Pressupostos!$G$21 -> 4.35 | E31: =Pressupostos!$G$20+Pressupostos!$G$21 -> 4.35 | F31: =Pressupostos!$G$20+Pressupostos!$G$21 -> 4.35 | G31: =Pressupostos!$G$20+Pressupostos!$G$21 -> 4.35
A32: Preço de venda Sprout (referência − desconto) | B32: €/kg | C32: =C31*(1-Pressupostos!$G$22) -> 4.35 | D32: =D31*(1-Pressupostos!$G$22) -> 4.35 | E32: =E31*(1-Pressupostos!$G$22) -> 4.35 | F32: =F31*(1-Pressupostos!$G$22) -> 4.35 | G32: =G31*(1-Pressupostos!$G$22) -> 4.35
A33: Embalamento | B33: €/kg | C33: =Pressupostos!$C$44 -> 0.45 | D33: =Pressupostos!$C$44 -> 0.45 | E33: =Pressupostos!$C$44 -> 0.45 | F33: =Pressupostos!$C$44 -> 0.45 | G33: =Pressupostos!$C$44 -> 0.45
